{
  "affected_release": null,
  "package_state": [
    {
      "product_name": "Red Hat Enterprise Linux 8",
      "fix_state": "Not affected",
      "package_name": "nodejs:10/nodejs",
      "cpe": "cpe:/o:redhat:enterprise_linux:8"
    },
    {
      "product_name": "Red Hat Enterprise Linux 8",
      "fix_state": "Not affected",
      "package_name": "nodejs:12/nodejs",
      "cpe": "cpe:/o:redhat:enterprise_linux:8"
    },
    {
      "product_name": "Red Hat Enterprise Linux 8",
      "fix_state": "Affected",
      "package_name": "nodejs:14/nodejs",
      "cpe": "cpe:/o:redhat:enterprise_linux:8"
    },
    {
      "product_name": "Red Hat Quay 3",
      "fix_state": "Under investigation",
      "package_name": "nodejs",
      "cpe": "cpe:/a:redhat:quay:3::el7"
    },
    {
      "product_name": "Red Hat Software Collections",
      "fix_state": "Not affected",
      "package_name": "rh-nodejs10-nodejs",
      "cpe": "cpe:/a:redhat:rhel_software_collections:3"
    },
    {
      "product_name": "Red Hat Software Collections",
      "fix_state": "Not affected",
      "package_name": "rh-nodejs12-nodejs",
      "cpe": "cpe:/a:redhat:rhel_software_collections:3"
    }
  ],
  "threat_severity": "Important",
  "public_date": "2020-09-15T00:00:00Z",
  "bugzilla": {
    "description": "CVE-2020-8251 nodejs: Denial of Service by resource exhaustion CWE-400 due to unfinished HTTP/1.1 requests",
    "id": "1879314",
    "url": "https://bugzilla.redhat.com/show_bug.cgi?id=1879314"
  },
  "cvss": {
    "cvss_base_score": "",
    "cvss_scoring_vector": "",
    "status": ""
  },
  "cvss3": {
    "cvss3_base_score": "7.5",
    "cvss3_scoring_vector": "CVSS:3.1/AV:N/AC:L/PR:N/UI:N/S:U/C:N/I:N/A:H",
    "status": "draft"
  },
  "iava": "",
  "cwe": "CWE-400",
  "statement": "",
  "acknowledgement": "",
  "name": "CVE-2020-8251",
  "document_distribution": "",
  "details": [
    "No description is available for this CVE."
  ],
  "references": null
}