{
  "affected_release": null,
  "package_state": [
    {
      "product_name": "Red Hat Ceph Storage 2",
      "fix_state": "Under investigation",
      "package_name": "python-django",
      "cpe": "cpe:/a:redhat:ceph_storage:2"
    },
    {
      "product_name": "Red Hat Ceph Storage 3",
      "fix_state": "Under investigation",
      "package_name": "python-django",
      "cpe": "cpe:/a:redhat:ceph_storage:3"
    },
    {
      "product_name": "Red Hat OpenStack Platform 10 (Newton)",
      "fix_state": "Under investigation",
      "package_name": "python-django",
      "cpe": "cpe:/a:redhat:openstack:10"
    },
    {
      "product_name": "Red Hat OpenStack Platform 13 (Queens)",
      "fix_state": "Under investigation",
      "package_name": "python-django",
      "cpe": "cpe:/a:redhat:openstack:13"
    },
    {
      "product_name": "Red Hat OpenStack Platform 15 (Stein)",
      "fix_state": "Under investigation",
      "package_name": "python-django",
      "cpe": "cpe:/a:redhat:openstack:15"
    },
    {
      "product_name": "Red Hat OpenStack Platform 16 (Train)",
      "fix_state": "Under investigation",
      "package_name": "python-django",
      "cpe": "cpe:/a:redhat:openstack:16"
    },
    {
      "product_name": "Red Hat Satellite 6",
      "fix_state": "Under investigation",
      "package_name": "python-django",
      "cpe": "cpe:/a:redhat:network_satellite:6"
    },
    {
      "product_name": "Red Hat Storage 3",
      "fix_state": "Under investigation",
      "package_name": "python-django",
      "cpe": "cpe:/a:redhat:storage:3"
    },
    {
      "product_name": "Red Hat Update Infrastructure 3 for Cloud Providers",
      "fix_state": "Affected",
      "package_name": "python-django",
      "cpe": "cpe:/a:redhat:rhui:3"
    }
  ],
  "threat_severity": "Moderate",
  "public_date": "2020-09-01T00:00:00Z",
  "bugzilla": {
    "description": "CVE-2020-24583 django: incorrect permissions on intermediate-level directories on Python 3.7+",
    "id": "1874485",
    "url": "https://bugzilla.redhat.com/show_bug.cgi?id=1874485"
  },
  "cvss": {
    "cvss_base_score": "",
    "cvss_scoring_vector": "",
    "status": ""
  },
  "cvss3": {
    "cvss3_base_score": "7.5",
    "cvss3_scoring_vector": "CVSS:3.1/AV:N/AC:L/PR:N/UI:N/S:U/C:H/I:N/A:N",
    "status": "draft"
  },
  "iava": "",
  "cwe": "CWE-276",
  "statement": "",
  "acknowledgement": "",
  "name": "CVE-2020-24583",
  "document_distribution": "",
  "details": [
    "An issue was discovered in Django 2.2 before 2.2.16, 3.0 before 3.0.10, and 3.1 before 3.1.1 (when Python 3.7+ is used). FILE_UPLOAD_DIRECTORY_PERMISSIONS mode was not applied to intermediate-level directories created in the process of uploading files. It was also not applied to intermediate-level collected static directories when using the collectstatic management command."
  ],
  "references": null
}