{
  "PublicDateAtUSN": "0001-01-01T00:00:00Z",
  "CRD": "2020-09-01T10:00:00Z",
  "Candidate": "CVE-2020-24583",
  "PublicDate": "2020-09-01T10:00:00Z",
  "References": [
    "https://cve.mitre.org/cgi-bin/cvename.cgi?name=CVE-2020-24583"
  ],
  "Description": "Incorrect permissions on intermediate-level directories on Python 3.7+",
  "UbuntuDescription": "",
  "Notes": [
    "mdeslaur\u003e This issue is caused by a behavioural change in Python 3.7.",
    "mdeslaur\u003e While python3.7 is available for bionic, it doesn't replace",
    "mdeslaur\u003e python3.6, so bionic is not affected by this issue."
  ],
  "Bugs": null,
  "Priority": "medium",
  "DiscoveredBy": "",
  "AssignedTo": "mdeslaur",
  "Patches": {
    "python-django": {
      "bionic": {
        "Status": "not-affected",
        "Note": "doesn't use python3.7"
      },
      "devel": {
        "Status": "needed",
        "Note": ""
      },
      "focal": {
        "Status": "needed",
        "Note": ""
      },
      "precise/esm": {
        "Status": "DNE",
        "Note": ""
      },
      "trusty": {
        "Status": "ignored",
        "Note": "out of standard support"
      },
      "trusty/esm": {
        "Status": "not-affected",
        "Note": "doesn't use python3.7"
      },
      "upstream": {
        "Status": "pending",
        "Note": "2.2.16"
      },
      "xenial": {
        "Status": "not-affected",
        "Note": "doesn't use python3.7"
      }
    }
  },
  "UpstreamLinks": {}
}