{
  "configurations": {
    "CVE_data_version": "4.0",
    "nodes": []
  },
  "cve": {
    "CVE_data_meta": {
      "ASSIGNER": "cve@mitre.org",
      "ID": "CVE-2020-29651"
    },
    "data_format": "MITRE",
    "data_type": "CVE",
    "data_version": "4.0",
    "description": {
      "description_data": [
        {
          "lang": "en",
          "value": "A denial of service via regular expression in the py.path.svnwc component of py (aka python-py) through 1.9.0 could be used by attackers to cause a compute-time denial of service attack by supplying malicious input to the blame functionality."
        }
      ]
    },
    "problemtype": {
      "problemtype_data": [
        {
          "description": []
        }
      ]
    },
    "references": {
      "reference_data": [
        {
          "name": "https://github.com/pytest-dev/py/issues/256",
          "refsource": "MISC",
          "tags": [],
          "url": "https://github.com/pytest-dev/py/issues/256"
        },
        {
          "name": "https://github.com/pytest-dev/py/pull/257",
          "refsource": "MISC",
          "tags": [],
          "url": "https://github.com/pytest-dev/py/pull/257"
        },
        {
          "name": "https://github.com/pytest-dev/py/pull/257/commits/4a9017dc6199d2a564b6e4b0aa39d6d8870e4144",
          "refsource": "MISC",
          "tags": [],
          "url": "https://github.com/pytest-dev/py/pull/257/commits/4a9017dc6199d2a564b6e4b0aa39d6d8870e4144"
        }
      ]
    }
  },
  "impact": {},
  "lastModifiedDate": "2020-12-09T07:15Z",
  "publishedDate": "2020-12-09T07:15Z"
}