{
  "configurations": {
    "CVE_data_version": "4.0",
    "nodes": []
  },
  "cve": {
    "CVE_data_meta": {
      "ASSIGNER": "cve@mitre.org",
      "ID": "CVE-2020-24372"
    },
    "data_format": "MITRE",
    "data_type": "CVE",
    "data_version": "4.0",
    "description": {
      "description_data": [
        {
          "lang": "en",
          "value": "LuaJIT through 2.1.0-beta3 has an out-of-bounds read in lj_err_run in lj_err.c."
        }
      ]
    },
    "problemtype": {
      "problemtype_data": [
        {
          "description": []
        }
      ]
    },
    "references": {
      "reference_data": [
        {
          "name": "https://github.com/LuaJIT/LuaJIT/issues/603",
          "refsource": "MISC",
          "tags": [],
          "url": "https://github.com/LuaJIT/LuaJIT/issues/603"
        }
      ]
    }
  },
  "impact": {},
  "lastModifiedDate": "2020-08-17T18:04Z",
  "publishedDate": "2020-08-17T17:15Z"
}