{
  "configurations": {
    "CVE_data_version": "4.0",
    "nodes": []
  },
  "cve": {
    "CVE_data_meta": {
      "ASSIGNER": "cve@mitre.org",
      "ID": "CVE-2020-35917"
    },
    "data_format": "MITRE",
    "data_type": "CVE",
    "data_version": "4.0",
    "description": {
      "description_data": [
        {
          "lang": "en",
          "value": "An issue was discovered in the pyo3 crate before 0.12.4 for Rust. There is a reference-counting error and use-after-free in From\u003cPy\u003cT\u003e\u003e."
        }
      ]
    },
    "problemtype": {
      "problemtype_data": [
        {
          "description": []
        }
      ]
    },
    "references": {
      "reference_data": [
        {
          "name": "https://rustsec.org/advisories/RUSTSEC-2020-0074.html",
          "refsource": "MISC",
          "tags": [],
          "url": "https://rustsec.org/advisories/RUSTSEC-2020-0074.html"
        }
      ]
    }
  },
  "impact": {},
  "lastModifiedDate": "2020-12-31T09:15Z",
  "publishedDate": "2020-12-31T09:15Z"
}