{
  "configurations": {
    "CVE_data_version": "4.0",
    "nodes": []
  },
  "cve": {
    "CVE_data_meta": {
      "ASSIGNER": "cve@mitre.org",
      "ID": "CVE-2021-3116"
    },
    "data_format": "MITRE",
    "data_type": "CVE",
    "data_version": "4.0",
    "description": {
      "description_data": [
        {
          "lang": "en",
          "value": "before_upstream_connection in AuthPlugin in http/proxy/auth.py in proxy.py before 2.3.1 accepts incorrect Proxy-Authorization header data because of a boolean confusion (and versus or)."
        }
      ]
    },
    "problemtype": {
      "problemtype_data": [
        {
          "description": []
        }
      ]
    },
    "references": {
      "reference_data": [
        {
          "name": "https://cardaci.xyz/advisories/2021/01/10/proxy.py-2.3.0-broken-basic-authentication/",
          "refsource": "MISC",
          "tags": [],
          "url": "https://cardaci.xyz/advisories/2021/01/10/proxy.py-2.3.0-broken-basic-authentication/"
        },
        {
          "name": "https://github.com/abhinavsingh/proxy.py/pull/482/commits/9b00093288237f5073c403f2c4f62acfdfa8ed46",
          "refsource": "MISC",
          "tags": [],
          "url": "https://github.com/abhinavsingh/proxy.py/pull/482/commits/9b00093288237f5073c403f2c4f62acfdfa8ed46"
        },
        {
          "name": "https://pypi.org/project/proxy.py/2.3.1/#history",
          "refsource": "MISC",
          "tags": [],
          "url": "https://pypi.org/project/proxy.py/2.3.1/#history"
        }
      ]
    }
  },
  "impact": {},
  "lastModifiedDate": "2021-01-11T05:15Z",
  "publishedDate": "2021-01-11T05:15Z"
}