{
  "affected_release": null,
  "package_state": [
    {
      "product_name": "Red Hat Enterprise Linux 5",
      "fix_state": "Out of support scope",
      "package_name": "python",
      "cpe": "cpe:/o:redhat:enterprise_linux:5"
    },
    {
      "product_name": "Red Hat Enterprise Linux 6",
      "fix_state": "Under investigation",
      "package_name": "python",
      "cpe": "cpe:/o:redhat:enterprise_linux:6"
    },
    {
      "product_name": "Red Hat Enterprise Linux 7",
      "fix_state": "Under investigation",
      "package_name": "python",
      "cpe": "cpe:/o:redhat:enterprise_linux:7"
    },
    {
      "product_name": "Red Hat Enterprise Linux 7",
      "fix_state": "Under investigation",
      "package_name": "python3",
      "cpe": "cpe:/o:redhat:enterprise_linux:7"
    },
    {
      "product_name": "Red Hat Enterprise Linux 8",
      "fix_state": "Under investigation",
      "package_name": "python27:2.7/python2",
      "cpe": "cpe:/o:redhat:enterprise_linux:8"
    },
    {
      "product_name": "Red Hat Enterprise Linux 8",
      "fix_state": "Under investigation",
      "package_name": "python3",
      "cpe": "cpe:/o:redhat:enterprise_linux:8"
    },
    {
      "product_name": "Red Hat Enterprise Linux 8",
      "fix_state": "Not affected",
      "package_name": "python36:3.6/python36",
      "cpe": "cpe:/o:redhat:enterprise_linux:8"
    },
    {
      "product_name": "Red Hat Enterprise Linux 8",
      "fix_state": "Under investigation",
      "package_name": "python38:3.8/python38",
      "cpe": "cpe:/o:redhat:enterprise_linux:8"
    },
    {
      "product_name": "Red Hat Software Collections",
      "fix_state": "Under investigation",
      "package_name": "python27-python",
      "cpe": "cpe:/a:redhat:rhel_software_collections:3"
    },
    {
      "product_name": "Red Hat Software Collections",
      "fix_state": "Under investigation",
      "package_name": "rh-python38-python",
      "cpe": "cpe:/a:redhat:rhel_software_collections:3"
    }
  ],
  "threat_severity": "Important",
  "public_date": "2021-01-19T00:00:00Z",
  "bugzilla": {
    "description": "CVE-2021-3177 python: buffer overflow in PyCArg_repr in _ctypes/callproc.c may lead to RCE",
    "id": "1918168",
    "url": "https://bugzilla.redhat.com/show_bug.cgi?id=1918168"
  },
  "cvss": {
    "cvss_base_score": "",
    "cvss_scoring_vector": "",
    "status": ""
  },
  "cvss3": {
    "cvss3_base_score": "9.0",
    "cvss3_scoring_vector": "CVSS:3.1/AV:N/AC:H/PR:N/UI:N/S:C/C:H/I:H/A:H",
    "status": "draft"
  },
  "iava": "",
  "cwe": "CWE-120",
  "statement": "",
  "acknowledgement": "",
  "name": "CVE-2021-3177",
  "document_distribution": "",
  "details": [
    "Python 3.x through 3.9.1 has a buffer overflow in PyCArg_repr in _ctypes/callproc.c, which may lead to remote code execution in certain Python applications that accept floating-point numbers as untrusted input, as demonstrated by a 1e300 argument to c_double.from_param. This occurs because sprintf is used unsafely."
  ],
  "references": null
}